<?xml version="1.0"?>
<robot xmlns:xacro="http://ros.org/wiki/xacro">
  <xacro:macro name="palm" params="
    prefix
    joint_limits_parameters_file
    physical_parameters_file
    visual_parameters_file"
  >
    <!-- Load configuration data from the provided .yaml files -->
    <xacro:read_model_data
      joint_limits_parameters_file="${joint_limits_parameters_file}"
      physical_parameters_file="${physical_parameters_file}"
      visual_parameters_file="${visual_parameters_file}"
    />

    <link name="${prefix}palm">
      <visual>
        <geometry>
          <mesh filename="${palm_visual_mesh}" />
        </geometry>
        <material name="${palm_visual_material_name}">
          <color rgba="${palm_visual_material_color}"/>
        </material>
      </visual>
      <collision>
        <geometry>
          <mesh filename="${palm_collision_mesh}" />
        </geometry>
      </collision>
      <inertial>
        <origin xyz="${palm_origin_xyz}" rpy="${palm_origin_rpy}"/>
        <mass value="${palm_mass}"/>
        <inertia ixx="${palm_ixx}" ixy="${palm_ixy}" ixz="${palm_ixz}" iyy="${palm_iyy}" iyz="${palm_iyz}" izz="${palm_izz}" />
      </inertial>
    </link>

    <joint name="${prefix}palm_finger_1_joint" type="revolute">
      <parent link="${prefix}palm"/>
      <child link="${prefix}finger_1_link_0"/>
      <axis xyz="0 1 0"/>
      <origin xyz="${palm_finger_1_joint_origin_xyz}" rpy="${palm_finger_1_joint_origin_rpy}"/>
      <limit lower="${palm_finger_1_joint_lower_limit}"
             upper="${palm_finger_1_joint_upper_limit}"
             effort="${palm_finger_1_joint_effort_limit}"
             velocity="${palm_finger_1_joint_velocity_limit}"/>
    </joint>
    <joint name="${prefix}palm_finger_2_joint" type="revolute">
      <parent link="${prefix}palm"/>
      <child link="${prefix}finger_2_link_0"/>
      <axis xyz="0 1 0"/>
      <origin xyz="${palm_finger_2_joint_origin_xyz}" rpy="${palm_finger_2_joint_origin_rpy}"/>
      <limit lower="${palm_finger_2_joint_lower_limit}"
             upper="${palm_finger_2_joint_upper_limit}"
             effort="${palm_finger_2_joint_effort_limit}"
             velocity="${palm_finger_2_joint_velocity_limit}"/>
    </joint>
    <joint name="${prefix}palm_finger_middle_joint" type="fixed">
      <parent link="${prefix}palm"/>
      <child link="${prefix}finger_middle_link_0"/>
      <axis xyz="0 0 1"/>
      <origin xyz="${palm_finger_middle_joint_origin_xyz}" rpy="${palm_finger_middle_joint_origin_rpy}"/>
    </joint>
  </xacro:macro>
</robot>
